<mujoco model="leap_rh">
  <compiler angle="radian" autolimits="true"/>

  <option timestep="0.01" integrator="Euler" iterations="5" ls_iterations="8">
    <flag eulerdamp="disable"/>
  </option>

  <custom>
    <numeric data="30" name="max_contact_points"/>
    <numeric data="12" name="max_geom_pairs"/>
  </custom>

  <asset>
    <material name="black" rgba="0.2 0.2 0.2 1"/>
    <material name="gray" rgba="0.5 0.5 0.5 1"/>
    <mesh name="leap_mount" file="meshes/leap_mount.obj"/>

    <mesh name="palm" file="../../../../../mujoco_menagerie/leap_hand/assets/palm_right.obj"/>
    <mesh name="base" file="../../../../../mujoco_menagerie/leap_hand/assets/base.obj"/>
    <mesh name="proximal" file="../../../../../mujoco_menagerie/leap_hand/assets/proximal.obj"/>
    <mesh name="medial" file="../../../../../mujoco_menagerie/leap_hand/assets/medial.obj"/>
    <mesh name="distal" file="../../../../../mujoco_menagerie/leap_hand/assets/distal.obj"/>
    <mesh name="tip" file="../../../../../mujoco_menagerie/leap_hand/assets/tip.obj"/>
    <mesh name="thumb_base" file="../../../../../mujoco_menagerie/leap_hand/assets/thumb_base.obj"/>
    <mesh name="thumb_proximal" file="../../../../../mujoco_menagerie/leap_hand/assets/thumb_proximal.obj"/>
    <mesh name="thumb_distal" file="../../../../../mujoco_menagerie/leap_hand/assets/thumb_distal.obj"/>
    <mesh name="thumb_tip" file="../../../../../mujoco_menagerie/leap_hand/assets/thumb_tip.obj"/>

    <mesh name="link_base" content_type="model/stl" file="link_base.stl" />
    <mesh name="link1" content_type="model/stl" file="link1.stl" />
    <mesh name="link2" content_type="model/stl" file="link2.stl" />
    <mesh name="link3" content_type="model/stl" file="link3.stl" />
    <mesh name="link4" content_type="model/stl" file="link4.stl" />
    <mesh name="link5" content_type="model/stl" file="link5.stl" />
    <mesh name="link6" content_type="model/stl" file="link6.stl" />
    <mesh name="end_tool" content_type="model/stl" file="end_tool.stl" />
  </asset>

  <default>
    <default class="leap_rh">
      <geom group="3" friction="0.2" solref="0.02 1.5" solimp="0.9 0.99 0.001"/>
      <default class="visual">
        <geom group="2" type="mesh" contype="0" conaffinity="0" density="0" material="black"/>
      </default>
      <default class="tip">
        <!-- <geom type="capsule" size="0.012 0.008" pos="0 -0.03 0.015" quat="1 1 0 0" friction="0.7 0.05 0.0002"/> -->
        <geom size="0.01 0.012 0.016" pos="-0.0012969 -0.0335524 0.0145207" quat="0.703552 0.709596 -0.0292107 -0.0252203" type="box" friction="0.7 0.05 0.0002" rgba=".5 .5 .5 .3"/>
      </default>
      <default class="thumb_tip">
        <!-- <geom type="capsule" size="0.012 0.008" pos="0.0 -0.04 -0.015" quat="1 1 0 0" friction="0.7 0.05 0.0002"/> -->
        <geom size="0.01 0.012 0.016" pos="-0.00127744 -0.0455619 -0.0144774" quat="0.708101 0.705072 -0.0294902 -0.024426" type="box" friction="0.7 0.05 0.0002" rgba=".5 .5 .5 .3"/>
      </default>

      <position kp="3.0" inheritrange="1"/>
      <!-- armature = rotor inertia * gear ratio^2 = 1.7 * 1e-8 * 288*288 = 0.00149376 -->
      <!-- max torque = 0.2196 = 600/1000*0.366 -->
      <!-- frictionloss = rough guess, small ish value -->
      <!-- <joint axis="0 0 -1" damping="0.2" armature="0.00149376" frictionloss="0.02" actuatorfrcrange="-0.2196 0.2196"/> -->
      <joint axis="0 0 -1" damping="0.2" armature="0.00149376" actuatorfrcrange="-0.2196 0.2196" frictionloss="0.02"/>

      <default class="mcp">
        <joint range="-0.314 2.23"/>
      </default>
      <default class="rot">
        <joint range="-1.047 1.047"/>
      </default>
      <default class="pip">
        <joint range="-0.506 1.885"/>
      </default>
      <default class="dip">
        <joint range="-0.366 2.042"/>
      </default>
      <default class="thumb_cmc">
        <joint range="-0.349 2.094"/>
      </default>
      <default class="thumb_axl">
        <joint range="-0.349 2.094"/>
      </default>
      <default class="thumb_mcp">
        <joint range="-0.47 2.443"/>
      </default>
      <default class="thumb_ipl">
        <joint range="-1.34 1.88"/>
      </default>

    </default>
  </default>

  <contact>
    <!-- filter the palm from all other finger bodies except the tips -->
    <exclude body1="palm" body2="if_bs"/>
    <exclude body1="palm" body2="mf_bs"/>
    <exclude body1="palm" body2="rf_bs"/>
    <exclude body1="palm" body2="th_mp"/>

    <exclude body1="palm" body2="if_px"/>
    <exclude body1="palm" body2="mf_px"/>
    <exclude body1="palm" body2="rf_px"/>
    <exclude body1="palm" body2="th_bs"/>

    <exclude body1="palm" body2="if_md"/>
    <exclude body1="palm" body2="mf_md"/>
    <exclude body1="palm" body2="rf_md"/>
    <exclude body1="palm" body2="th_px"/>

    <!-- none of the base fingertip geoms can touch each other -->
    <exclude body1="if_bs" body2="mf_bs"/>
    <exclude body1="if_bs" body2="rf_bs"/>
    <exclude body1="mf_bs" body2="rf_bs"/>

    <exclude body1="th_mp" body2="if_bs"/>
    <exclude body1="th_mp" body2="mf_bs"/>
    <exclude body1="th_mp" body2="rf_bs"/>
  </contact>

  <worldbody>
    <light name="spotlight" mode="targetbodycom" target="palm" pos="3 0 4"/>
    <body name="root" pos="0 0 0" quat="1 0 0 0">
      <geom type="mesh" contype="0" conaffinity="0" group="1" rgba="1 1 1 1" mesh="link_base" />
      
      <body name="link1" pos="0 0 0.267">
        <inertial pos="-0.0002 0.02905 -0.01233" quat="0.978953 -0.202769 -0.00441617 -0.0227264" mass="2.382" diaginertia="0.00569127 0.00533384 0.00293865" />
        <joint name="joint1" pos="0 0 0" axis="0 0 1" range="-6.28319 6.28319" actuatorfrcrange="-50 50" damping="1" frictionloss="1" />
        <geom name="link1_0" type="mesh" contype="0" conaffinity="0" group="1" mesh="link1" />
        <geom name="link1_1" type="mesh" rgba="1 1 1 1" mesh="link1" />

        <body name="link2" quat="0.707105 -0.707108 0 0">
          <inertial pos="0.00022 -0.12856 0.01735" quat="0.50198 0.86483 -0.00778841 0.00483285" mass="1.869" diaginertia="0.00959898 0.00937717 0.00201315" />
          <joint name="joint2" pos="0 0 0" axis="0 0 1" range="-2.059 2.0944" actuatorfrcrange="-50 50" damping="1" frictionloss="1" />
          <geom name="link2_0" type="mesh" contype="0" conaffinity="0" group="1" mesh="link2" />
          <geom name="link2_1" type="mesh" rgba="1 1 1 1" mesh="link2" />

          <body name="link3" pos="0 -0.293 0" quat="0.707105 0.707108 0 0">
            <inertial pos="0.0466 -0.02463 -0.00768" quat="0.913819 0.289775 0.281481 -0.0416455" mass="1.6383" diaginertia="0.00351721 0.00294089 0.00195868" />
            <joint name="joint3" pos="0 0 0" axis="0 0 1" range="-6.28319 6.28319" actuatorfrcrange="-30 30" damping="1" frictionloss="1" />
            <geom name="link3_0" type="mesh" contype="0" conaffinity="0" group="1" mesh="link3" />
            <geom name="link3_1" type="mesh" rgba="1 1 1 1" mesh="link3" />

            <body name="link4" pos="0.0525 0 0" quat="0.707105 0.707108 0 0">
              <inertial pos="0.07047 -0.11575 0.012" quat="0.422108 0.852026 -0.126025 0.282832" mass="1.7269" diaginertia="0.00657137 0.00647948 0.00186763" />
              <joint name="joint4" pos="0 0 0" axis="0 0 1" range="-0.19198 3.927" actuatorfrcrange="-50 50" damping="1" frictionloss="1" />
              <geom name="link4_0" type="mesh" contype="0" conaffinity="0" group="1" mesh="link4" />
              <geom name="link4_1" type="mesh" rgba="1 1 1 1" mesh="link4" />
              
              <body name="link5" pos="0.0775 -0.3425 0" quat="0.707105 0.707108 0 0">
                <inertial pos="-0.00032 0.01604 -0.026" quat="0.999311 -0.0304457 0.000577067 0.0212082" mass="1.3203" diaginertia="0.00534729 0.00499076 0.0013489" />
                <joint name="joint5" pos="0 0 0" axis="0 0 1" range="-6.28319 6.28319" actuatorfrcrange="-30 30" damping="1" frictionloss="1" />
                <geom name="link5_0" type="mesh" contype="0" conaffinity="0" group="1" mesh="link5" />
                <geom name="link5_1" type="mesh" rgba="1 1 1 1" mesh="link5" />

                <body name="link6" quat="0.707105 0.707108 0 0">
                  <inertial pos="0.06469 0.03278 0.02141" quat="-0.217672 0.772419 0.16258 0.574069" mass="1.325" diaginertia="0.00245421 0.00221646 0.00107273" />
                  <joint name="joint6" pos="0 0 0" axis="0 0 1" range="-1.69297 3.14159" actuatorfrcrange="-20 20" damping="1" frictionloss="1" />
                  <geom name="link6_0" type="mesh" contype="0" conaffinity="0" group="1" mesh="link6" />
                  <geom name="link6_1" type="mesh" rgba="1 1 1 1" mesh="link6" />

                  <body name="link7" pos="0.076 0.097 0" quat="0.707105 -0.707108 0 0">
                    <inertial pos="0.0111282 -0.0247354 0.02926" quat="0.821323 0.399259 0.33612 -0.230313" mass="0.708593" diaginertia="0.00206985 0.0019818 0.000792212" />
                    <joint name="joint7" pos="0 0 0" axis="0 0 1" range="-6.28319 6.28319" actuatorfrcrange="-30 30" damping="1" frictionloss="1" />
                    <geom name="link7_0" type="mesh" rgba="0.753 0.753 0.753 1" mesh="end_tool" contype="1" conaffinity="0" density="0" group="1"/>
                    <geom name="ft_sensor_collision" size="0.04 0.03" pos="0 0 0.028" type="cylinder" rgba="1 1 1 1" contype="1" conaffinity="0" density="0" group="1"/>
                    <body name="palm" pos="0.06 -0.035 0.07" quat="-3.67321e-06 1 0 0" childclass="leap_rh">
                      <inertial pos="-0.049542 -0.042914 -0.010227" quat="0.565586 0.427629 -0.574956 0.408254" mass="0.237"
                        diaginertia="0.000407345 0.000304759 0.000180736"/>
                      <geom name="palm_visual" pos="-0.02 0.02575 -0.0347" quat="1 0 0 0" class="visual" mesh="palm"/>
                      <geom name="palm_collision_1" size="0.011 0.013 0.017" pos="-0.009 0.008 -0.011" type="box"/>
                      <geom name="palm_collision_2" size="0.011 0.013 0.017" pos="-0.009 -0.037 -0.011" type="box"/>
                      <geom name="palm_collision_3" size="0.011 0.013 0.017" pos="-0.009 -0.082 -0.011" type="box"/>
                      <geom name="palm_collision_4" size="0.029 0.01 0.023" pos="-0.066 -0.078 -0.0115" quat="0.989016 0 0 -0.147806" type="box"/>
                      <geom name="palm_collision_5" size="0.01 0.06 0.015" pos="-0.03 -0.035 -0.003" type="box"/>
                      <geom name="palm_collision_6" size="0.005 0.06 0.01" pos="-0.032 -0.035 -0.024" quat="0.923956 0 0.382499 0" type="box"/>
                      <geom name="palm_collision_7" size="0.012 0.058 0.023" pos="-0.048 -0.033 -0.0115" type="box"/>
                      <geom name="palm_collision_8" size="0.022 0.026 0.023" pos="-0.078 -0.053 -0.0115" type="box"/>
                      <geom name="palm_collision_9" size="0.002 0.018 0.017" pos="-0.098 -0.009 -0.006" type="box"/>
                      <geom name="palm_collision_10" size="0.022 0.028 0.002" pos="-0.078 -0.003 0.01" type="box"/>
                      <body name="if_bs" pos="-0.007 0.023 -0.0187" quat="0.5 0.5 0.5 -0.5">
                        <inertial pos="-0.022516 0.033882 0.016359" quat="0.388092 0.677951 -0.247713 0.573067" mass="0.044"
                          diaginertia="1.74972e-05 1.61504e-05 7.21342e-06"/>
                        <joint name="if_mcp" class="mcp"/>
                        <geom name="if_bs_visual" pos="0.0084 0.0077 0.01465" quat="1 0 0 0" class="visual" mesh="base"/>
                        <geom name="if_bs_collision_1" size="0.01 0.003 0.017" pos="0 0.018 0.0147" type="box"/>
                        <body name="if_px" pos="-0.0122 0.0381 0.0145" quat="0.500003 -0.5 -0.499997 0.5">
                          <inertial pos="0.0075 -0.0002 -0.011" quat="0 0.707107 0 0.707107" mass="0.032"
                            diaginertia="4.8853e-06 4.3733e-06 3.0933e-06"/>
                          <joint name="if_rot" class="rot"/>
                          <geom name="if_px_visual" pos="0.0096 0.0002 0.0007" quat="0.500003 -0.5 -0.5 -0.499997" class="visual"
                            mesh="proximal"/>
                          <geom name="if_px_collision" size="0.017 0.013 0.011" pos="0.0075 -0.0002 -0.011" type="box"/>

                          <body name="if_md" pos="0.015 0.0143 -0.013" quat="0.500003 0.5 -0.5 0.499997">
                            <inertial pos="0.0054215 -0.029148 0.015" quat="0.687228 0.687228 0.166487 0.166487" mass="0.037"
                              diaginertia="8.28004e-06 8.1598e-06 5.39516e-06"/>
                            <joint name="if_pip" class="pip"/>
                            <geom name="if_md_visual" pos="0.0211 -0.0084 0.0097" quat="2.67949e-08 -1 0 0" class="visual"
                              mesh="medial"/>
                            <geom name="if_md_collision_1" size="0.008 0.003 0.013" pos="0 -0.02 0.015" type="box"/>
                            <geom name="if_md_collision_5" size="0.017 0.011 0.013" pos="0.0075 -0.035 0.015" type="box"/>
                            <body name="if_ds" pos="0 -0.0361 0.0002">
                              <inertial pos="-0.0008794 -0.027019 0.014594" quat="0.702905 0.710643 -0.0212937 -0.0214203"
                                mass="0.016" diaginertia="3.71863e-06 3.02396e-06 1.6518e-06"/>
                              <joint name="if_dip" class="dip"/>
                              <geom name="if_ds_visual" pos="0.0132 -0.0061 0.0144" quat="2.67949e-08 1 0 0" class="visual"
                                mesh="distal"/>
                              <geom name="if_ds_collision_1" size="0.01 0.003 0.015" pos="0 -0.017 0.015" type="box"/>
                              <geom name="if_tip" class="tip"/>
                              <geom type="mesh" mesh="tip" class="visual" material="gray"/>
                              <site name="if_tip" pos="0 -0.05 0.015" group="4"/>
                            </body>
                          </body>
                        </body>
                      </body>
                      <body name="mf_bs" pos="-0.0071 -0.0224 -0.0187" quat="0.500003 0.5 0.5 -0.499997">
                        <inertial pos="-0.022516 0.033882 0.016359" quat="0.388092 0.677951 -0.247713 0.573067" mass="0.044"
                          diaginertia="1.74972e-05 1.61504e-05 7.21342e-06"/>
                        <joint name="mf_mcp" class="mcp"/>
                        <geom name="mf_bs_visual" pos="0.0084 0.0077 0.01465" quat="1 0 0 0" class="visual" mesh="base"/>
                        <geom name="mf_bs_collision_1" size="0.01 0.003 0.017" pos="0 0.018 0.0147" type="box"/>
                        <body name="mf_px" pos="-0.0122 0.0381 0.0145" quat="0.500003 -0.5 -0.499997 0.5">
                          <inertial pos="0.0075 -0.0002 -0.011" quat="0 0.707107 0 0.707107" mass="0.032"
                            diaginertia="4.8853e-06 4.3733e-06 3.0933e-06"/>
                          <joint name="mf_rot" class="rot"/>
                          <geom name="mf_px_visual" pos="0.0096 0.0003 0.0007" quat="0.500003 -0.5 -0.5 -0.499997" class="visual"
                            mesh="proximal"/>
                          <geom name="mf_px_collision" size="0.017 0.013 0.011" pos="0.0075 -0.0002 -0.011" type="box"/>
                          <body name="mf_md" pos="0.015 0.0143 -0.013" quat="0.500003 0.5 -0.5 0.499997">
                            <inertial pos="0.0054215 -0.029148 0.015" quat="0.687228 0.687228 0.166487 0.166487" mass="0.037"
                              diaginertia="8.28004e-06 8.1598e-06 5.39516e-06"/>
                            <joint name="mf_pip" class="pip"/>
                            <geom name="mf_md_visual" pos="0.0211 -0.0084 0.0097" quat="1.32679e-06 -1 0 0" class="visual"
                              mesh="medial"/>
                            <geom name="mf_md_collision_1" size="0.008 0.003 0.013" pos="0 -0.02 0.015" type="box"/>
                            <geom name="mf_md_collision_5" size="0.017 0.011 0.013" pos="0.0075 -0.035 0.015" type="box"/>
                            <body name="mf_ds" pos="0 -0.0361 0.0002">
                              <inertial pos="-0.0008794 -0.027019 0.014594" quat="0.702905 0.710643 -0.0212937 -0.0214203"
                                mass="0.016" diaginertia="3.71863e-06 3.02396e-06 1.6518e-06"/>
                              <joint name="mf_dip" class="dip"/>
                              <geom name="mf_ds_visual" pos="0.0132 -0.0061 0.0145" quat="1.32679e-06 1 0 0" class="visual"
                                mesh="distal"/>
                              <geom name="mf_ds_collision_1" size="0.01 0.003 0.015" pos="0 -0.017 0.015" type="box"/>
                              <geom name="mf_tip" class="tip"/>
                              <geom type="mesh" mesh="tip" class="visual" material="gray"/>
                              <site name="mf_tip" pos="0 -0.05 0.015" group="4"/>
                            </body>
                          </body>
                        </body>
                      </body>
                      <body name="rf_bs" pos="-0.00709 -0.0678 -0.0187" quat="0.500003 0.5 0.5 -0.499997">
                        <inertial pos="-0.022516 0.033882 0.016359" quat="0.388092 0.677951 -0.247713 0.573067" mass="0.044"
                          diaginertia="1.74972e-05 1.61504e-05 7.21342e-06"/>
                        <joint name="rf_mcp" class="mcp"/>
                        <geom name="rf_bs_visual" pos="0.0084 0.0077 0.01465" quat="1 0 0 0" class="visual" mesh="base"/>
                        <geom name="rf_bs_collision_1" size="0.01 0.003 0.017" pos="0 0.018 0.0147" type="box"/>
                        <body name="rf_px" pos="-0.0122 0.0381 0.0145" quat="0.500003 -0.5 -0.499997 0.5">
                          <inertial pos="0.0075 -0.0002 -0.011" quat="0 0.707107 0 0.707107" mass="0.032"
                            diaginertia="4.8853e-06 4.3733e-06 3.0933e-06"/>
                          <joint name="rf_rot" class="rot"/>
                          <geom name="rf_px_visual" pos="0.0096 0.0003 0.0007" quat="0.500003 -0.5 -0.5 -0.499997" class="visual"
                            mesh="proximal"/>
                          <geom name="rf_px_collision" size="0.017 0.013 0.011" pos="0.0075 -0.0002 -0.011" type="box"/>
                          <body name="rf_md" pos="0.015 0.0143 -0.013" quat="0.500003 0.5 -0.5 0.499997">
                            <inertial pos="0.0054215 -0.029148 0.015" quat="0.687228 0.687228 0.166487 0.166487" mass="0.037"
                              diaginertia="8.28004e-06 8.1598e-06 5.39516e-06"/>
                            <joint name="rf_pip" class="pip"/>
                            <geom name="rf_md_visual" pos="0.0211 -0.0084 0.0097" quat="0 -1 0 0" class="visual" mesh="medial"/>
                            <geom name="rf_md_collision_1" size="0.008 0.003 0.013" pos="0 -0.02 0.015" type="box"/>
                            <geom name="rf_md_collision_5" size="0.017 0.011 0.013" pos="0.0075 -0.035 0.015" type="box"/>
                            <body name="rf_ds" pos="0 -0.03609 0.0002">
                              <inertial pos="-0.0008794 -0.027019 0.014594" quat="0.702905 0.710643 -0.0212937 -0.0214203"
                                mass="0.016" diaginertia="3.71863e-06 3.02396e-06 1.6518e-06"/>
                              <joint name="rf_dip" class="dip"/>
                              <geom name="rf_ds_visual" pos="0.0132 -0.0061 0.0145" quat="0 1 0 0" class="visual" mesh="distal"/>
                              <geom name="rf_ds_collision_1" size="0.01 0.003 0.015" pos="0 -0.017 0.015" type="box"/>
                              <geom name="rf_tip" class="tip"/>
                              <geom type="mesh" mesh="tip" class="visual" material="gray"/>
                              <site name="rf_tip" pos="0 -0.05 0.015" group="4"/>
                            </body>
                          </body>
                        </body>
                      </body>
                      <body name="th_mp" pos="-0.0693 -0.0012 -0.0216" quat="0.707109 0 0.707105 0">
                        <inertial pos="0.0075 -0.0002 -0.011" quat="0 0.707107 0 0.707107" mass="0.032"
                          diaginertia="4.8853e-06 4.3733e-06 3.0933e-06"/>
                        <joint name="th_cmc" class="thumb_cmc"/>
                        <geom name="th_mp_visual" pos="-0.0053 0.0003 0.00078" quat="0.500003 -0.5 -0.5 -0.499997" class="visual"
                          mesh="proximal"/>
                        <geom name="th_mp_collision" size="0.017 0.013 0.011" pos="-0.0075 -0.0002 -0.011" type="box"/>
                        <body name="th_bs" pos="0 0.0143 -0.013" quat="0.500003 0.5 -0.5 0.499997">
                          <inertial pos="0 0 -0.0070806" quat="0.707107 0.707107 0 0" mass="0.003"
                            diaginertia="6.1932e-07 5.351e-07 2.1516e-07"/>
                          <joint name="th_axl" class="thumb_axl"/>
                          <geom name="th_bs_collision_1" pos="0.01196 0 -0.0158" quat="0.707109 0.707105 0 0" class="visual" mesh="thumb_base"/>
                          <body name="th_px" pos="0 0.0145 -0.017" quat="0.707109 -0.707105 0 0">
                            <inertial pos="-0.0020593 0.015912 -0.013733" quat="0.698518 0.697382 -0.104933 0.121324" mass="0.038"
                              diaginertia="9.87104e-06 9.32653e-06 4.36203e-06"/>
                            <joint name="th_mcp" class="thumb_mcp"/>
                            <geom name="th_px_visual" pos="0.0439 0.0579 -0.0086" quat="1 0 0 0" class="visual" mesh="thumb_proximal"/>
                            <geom name="th_px_collision_1" size="0.01 0.02 0.012" pos="0 0.0105 -0.014" type="box"/>
                            <body name="th_ds" pos="0 0.0466 0.0002" quat="1.32679e-06 0 0 1">
                              <inertial pos="0.00096191 -0.024203 -0.014419" quat="0.35287 0.311272 -0.632839 0.614904" mass="0.049"
                                diaginertia="2.08591e-05 2.0402e-05 4.71335e-06"/>
                              <joint name="th_ipl" class="thumb_ipl"/>
                              <geom name="th_ds_visual" pos="0.0625 0.0784 0.0489" quat="1 0 0 0" class="visual" mesh="thumb_distal"/>
                              <geom name="th_ds_collision_1" size="0.01 0.018 0.012" pos="0 -0.0085 -0.015" type="box"/>
                              <geom name="th_tip" class="thumb_tip"/>
                              <site name="th_tip" pos="0 -0.06 -0.015" group="4"/>
                              <geom type="mesh" mesh="thumb_tip" class="visual" material="gray"/>
                            </body>
                          </body>
                        </body>
                      </body>
                    </body>
                  </body>
                </body>
              </body>
            </body>
          </body>
        </body>
      </body>
    </body>
  </worldbody>

  <actuator>
    <position name="if_mcp_act" joint="if_mcp" class="mcp"/>
    <position name="if_rot_act" joint="if_rot" class="rot"/>
    <position name="if_pip_act" joint="if_pip" class="pip"/>
    <position name="if_dip_act" joint="if_dip" class="dip"/>
    <position name="mf_mcp_act" joint="mf_mcp" class="mcp"/>
    <position name="mf_rot_act" joint="mf_rot" class="rot"/>
    <position name="mf_pip_act" joint="mf_pip" class="pip"/>
    <position name="mf_dip_act" joint="mf_dip" class="dip"/>
    <position name="rf_mcp_act" joint="rf_mcp" class="mcp"/>
    <position name="rf_rot_act" joint="rf_rot" class="rot"/>
    <position name="rf_pip_act" joint="rf_pip" class="pip"/>
    <position name="rf_dip_act" joint="rf_dip" class="dip"/>
    <position name="th_cmc_act" joint="th_cmc" class="thumb_cmc"/>
    <position name="th_axl_act" joint="th_axl" class="thumb_axl"/>
    <position name="th_mcp_act" joint="th_mcp" class="thumb_mcp"/>
    <position name="th_ipl_act" joint="th_ipl" class="thumb_ipl"/>

    <motor name="joint1" joint="joint1" ctrllimited="true" ctrlrange="-100 100" gear="1" />
    <motor name="joint2" joint="joint2" ctrllimited="true" ctrlrange="-100 100" gear="1" />
    <motor name="joint3" joint="joint3" ctrllimited="true" ctrlrange="-100 100" gear="1" />
    <motor name="joint4" joint="joint4" ctrllimited="true" ctrlrange="-100 100" gear="1" />
    <motor name="joint5" joint="joint5" ctrllimited="true" ctrlrange="-100 100" gear="1" />
    <motor name="joint6" joint="joint6" ctrllimited="true" ctrlrange="-100 100" gear="1" />
    <motor name="joint7" joint="joint7" ctrllimited="true" ctrlrange="-100 100" gear="1" />

  </actuator>
</mujoco>
