<mujoco model="xarm_leap_with_objects">
  <!-- <option iterations="50" timestep="0.001" solver="PGS" gravity="0 0 -9.81" integrator="RK4"/> -->
  <!-- <compiler angle="radian" meshdir="assets/meshes" eulerseq="zyx" autolimits="true" /> -->
  <compiler angle="radian" meshdir="assets/meshes" autolimits="true" />
  <option integrator="RK4"/>
  <!-- <option gravity="0 0 0" /> -->

  <default>
    <default class="cube">
      <geom friction=".3 0.05" conaffinity="2" condim="3"/>
    </default>
  </default>

  <asset>
    <!-- ground -->
    <texture type="skybox" builtin="gradient" rgb1="0.3 0.5 0.7" rgb2="0 0 0" width="512" height="3072"/>
    <texture type="2d" name="groundplane" builtin="checker" mark="edge" rgb1="0.2 0.3 0.4" rgb2="0.1 0.2 0.3"
    markrgb="0.8 0.8 0.8" width="300" height="300"/>
    <texture file="assets/textures/light-wood.png" name="woodplane" type="2d"/>
    <material name="groundplane" texture="woodplane" texuniform="true" texrepeat="5 5" reflectance="0.2"/>
    <!-- object-bottle -->
    <mesh file="./bottle.stl" name="bottle_mesh" scale="0.8 0.8 0.8"/>
    <texture type="skybox" file="assets/textures/glass.png" name="tex-glass"/>
    <material name="glass" reflectance="0.5" texrepeat="5 5" texture="tex-glass" texuniform="true"/>
    <mesh file="./bread.stl" name="bread_mesh" scale="1 1 1"/>
    <mesh file="./cup.stl" name="cup_mesh" scale="0.7 0.7 0.7"/>
    <mesh file="./bowl.stl" name="bowl_mesh" scale="0.7 0.7 0.7"/>
    <mesh file="./winnercup.stl" name="winnercup_mesh" scale="3e-4 3e-4 3e-4"/>
    <!-- object-can -->
    <mesh file="./can.stl" name="can_mesh"/>
    <texture file="assets/textures/soda.png" name="tex-can" type="2d"/>
    <material name="coke" reflectance="0.7" texrepeat="5 5" texture="tex-can" texuniform="true"/>
    <!-- object red can-->
    <texture file="assets/textures/red-wood.png" name="tex-red-can" type="2d"/>
    <material name="red-coke" reflectance="0.7" texrepeat="5 5" texture="tex-red-can" texuniform="true"/>
    <!-- xArm7 -->
    <mesh name="link_base" content_type="model/stl" file="link_base.stl" />
    <mesh name="link1" content_type="model/stl" file="link1.stl" />
    <mesh name="link2" content_type="model/stl" file="link2.stl" />
    <mesh name="link3" content_type="model/stl" file="link3.stl" />
    <mesh name="link4" content_type="model/stl" file="link4.stl" />
    <mesh name="link5" content_type="model/stl" file="link5.stl" />
    <mesh name="link6" content_type="model/stl" file="link6.stl" />
    <mesh name="end_tool" content_type="model/stl" file="end_tool.stl" />
    <!-- Leap Hand -->
    <mesh name="palm_lower" content_type="model/stl" file="palm_lower.stl" />
    <mesh name="mcp_joint" content_type="model/stl" file="mcp_joint.stl" />
    <mesh name="pip" content_type="model/stl" file="pip.stl" />
    <mesh name="dip" content_type="model/stl" file="dip.stl" />
    <mesh name="fingertip" content_type="model/stl" file="fingertip.stl" />
    <mesh name="thumb_pip" content_type="model/stl" file="thumb_pip.stl" />
    <mesh name="thumb_dip" content_type="model/stl" file="thumb_dip.stl" />
    <mesh name="thumb_fingertip" content_type="model/stl" file="thumb_fingertip.stl" />

    <texture name="cube" type="cube"
      fileup="assets/textures/fileup.png"
      fileback="assets/textures/fileback.png"
      filedown="assets/textures/filedown.png"
      filefront="assets/textures/filefront.png"
      fileleft="assets/textures/fileleft.png"
      fileright="assets/textures/fileright.png"/>
    <material name="cube" texture="cube"/>
    <texture name="graycube" type="cube"
      fileup="assets/textures/grayup.png"
      fileback="assets/textures/grayback.png"
      filedown="assets/textures/graydown.png"
      filefront="assets/textures/grayfront.png"
      fileleft="assets/textures/grayleft.png"
      fileright="assets/textures/grayright.png"/>
    <material name="graycube" texture="graycube"/>
    <texture name="dexcube" type="2d" file="assets/textures/dex_cube.png"/>
    <material name="dexcube" texture="dexcube"/>
    <mesh name="cube_mesh" file="dex_cube.obj" scale="0.035 0.035 0.035"/>
  </asset>

  <worldbody>
    <light pos="0 0 10" dir="0 0 -1" directional="true" diffuse="0.7 0.7 0.7" castshadow="true"/>
    <geom name="floor" size="0 0 0.05" type="plane" material="groundplane"/>
   
    <body name="root" pos="0 0 0" quat="1 0 0 0">
      <geom type="mesh" contype="0" conaffinity="0" group="1" rgba="1 1 1 1" mesh="link_base" />
      
      <body name="link1" pos="0 0 0.267">
        <inertial pos="-0.0002 0.02905 -0.01233" quat="0.978953 -0.202769 -0.00441617 -0.0227264" mass="2.382" diaginertia="0.00569127 0.00533384 0.00293865" />
        <joint name="joint1" pos="0 0 0" axis="0 0 1" range="-6.28319 6.28319" actuatorfrcrange="-50 50" damping="1" frictionloss="1" />
        <geom name="link1_0" type="mesh" contype="0" conaffinity="0" group="1" mesh="link1" />
        <geom name="link1_1" type="mesh" rgba="1 1 1 1" mesh="link1" />

        <body name="link2" quat="0.707105 -0.707108 0 0">
          <inertial pos="0.00022 -0.12856 0.01735" quat="0.50198 0.86483 -0.00778841 0.00483285" mass="1.869" diaginertia="0.00959898 0.00937717 0.00201315" />
          <joint name="joint2" pos="0 0 0" axis="0 0 1" range="-2.059 2.0944" actuatorfrcrange="-50 50" damping="1" frictionloss="1" />
          <geom name="link2_0" type="mesh" contype="0" conaffinity="0" group="1" mesh="link2" />
          <geom name="link2_1" type="mesh" rgba="1 1 1 1" mesh="link2" />

          <body name="link3" pos="0 -0.293 0" quat="0.707105 0.707108 0 0">
            <inertial pos="0.0466 -0.02463 -0.00768" quat="0.913819 0.289775 0.281481 -0.0416455" mass="1.6383" diaginertia="0.00351721 0.00294089 0.00195868" />
            <joint name="joint3" pos="0 0 0" axis="0 0 1" range="-6.28319 6.28319" actuatorfrcrange="-30 30" damping="1" frictionloss="1" />
            <geom name="link3_0" type="mesh" contype="0" conaffinity="0" group="1" mesh="link3" />
            <geom name="link3_1" type="mesh" rgba="1 1 1 1" mesh="link3" />

            <body name="link4" pos="0.0525 0 0" quat="0.707105 0.707108 0 0">
              <inertial pos="0.07047 -0.11575 0.012" quat="0.422108 0.852026 -0.126025 0.282832" mass="1.7269" diaginertia="0.00657137 0.00647948 0.00186763" />
              <joint name="joint4" pos="0 0 0" axis="0 0 1" range="-0.19198 3.927" actuatorfrcrange="-50 50" damping="1" frictionloss="1" />
              <geom name="link4_0" type="mesh" contype="0" conaffinity="0" group="1" mesh="link4" />
              <geom name="link4_1" type="mesh" rgba="1 1 1 1" mesh="link4" />
              
              <body name="link5" pos="0.0775 -0.3425 0" quat="0.707105 0.707108 0 0">
                <inertial pos="-0.00032 0.01604 -0.026" quat="0.999311 -0.0304457 0.000577067 0.0212082" mass="1.3203" diaginertia="0.00534729 0.00499076 0.0013489" />
                <joint name="joint5" pos="0 0 0" axis="0 0 1" range="-6.28319 6.28319" actuatorfrcrange="-30 30" damping="1" frictionloss="1" />
                <geom name="link5_0" type="mesh" contype="0" conaffinity="0" group="1" mesh="link5" />
                <geom name="link5_1" type="mesh" rgba="1 1 1 1" mesh="link5" />

                <body name="link6" quat="0.707105 0.707108 0 0">
                  <inertial pos="0.06469 0.03278 0.02141" quat="-0.217672 0.772419 0.16258 0.574069" mass="1.325" diaginertia="0.00245421 0.00221646 0.00107273" />
                  <joint name="joint6" pos="0 0 0" axis="0 0 1" range="-1.69297 3.14159" actuatorfrcrange="-20 20" damping="1" frictionloss="1" />
                  <geom name="link6_0" type="mesh" contype="0" conaffinity="0" group="1" mesh="link6" />
                  <geom name="link6_1" type="mesh" rgba="1 1 1 1" mesh="link6" />

                  <body name="link7" pos="0.076 0.097 0" quat="0.707105 -0.707108 0 0">
                    <inertial pos="0.0111282 -0.0247354 0.02926" quat="0.821323 0.399259 0.33612 -0.230313" mass="0.708593" diaginertia="0.00206985 0.0019818 0.000792212" />
                    <joint name="joint7" pos="0 0 0" axis="0 0 1" range="-6.28319 6.28319" actuatorfrcrange="-30 30" damping="1" frictionloss="1" />
                    <geom name="link7_0" type="mesh" rgba="0.753 0.753 0.753 1" mesh="end_tool" contype="1" conaffinity="0" density="0" group="1"/>
                    <geom name="ft_sensor_collision" size="0.04 0.03" pos="0 0 0.028" type="cylinder" rgba="1 1 1 1" contype="1" conaffinity="0" density="0" group="1"/>
                    <geom name="palm_lower" pos="0.0399048 -0.060758 0.102722" quat="-3.67321e-06 1 0 0" type="mesh" rgba="0.2 0.2 0.2 1" mesh="palm_lower" contype="1" conaffinity="0" density="0" group="1" friction="3.0 0.02 0.001"/>
                    <body name="palm_mass" pos="0.0399048 -0.060758 0.102722" quat="-3.67321e-06 1 0 0">
                      <inertial pos="0 0 0" quat="1 0 0 0" mass="0.237" diaginertia="7.96e-05 7.11e-05 3.28e-05" />
                    </body>
                    
                    <body name="mcp_joint" pos="0.0529048 -0.0580579 0.0867222" quat="-0.500002 0.499998 0.499998 0.500002">
                        <inertial pos="0 0 0" quat="0.388585 0.626468 -0.324549 0.592628" mass="0.044" diaginertia="1.47756e-05 1.31982e-05 6.0802e-06" />
                        <joint name="mcp_joint" pos="0 0 0" axis="0 0 -1" range="-0.314 2.23" actuatorfrcrange="-0.95 0.95" />
                         <geom name="mcp_joint_0" pos="0.0084069 0.00776624 0.0146574" type="mesh" contype="0" conaffinity="0" group="1" rgba="0.2 0.2 0.2 1" mesh="mcp_joint" friction="0.5 0.05 0.01" />
                         <geom name="mcp_joint_1" pos="0.0084069 0.00776624 0.0146574" type="mesh" rgba="0.2 0.2 0.2 1" mesh="mcp_joint" friction="0.5 0.05 0.01"/>


                      <body name="pip" pos="-0.0122 0.0381 0.0145" quat="0.5 -0.5 -0.5 0.5">
                          <inertial pos="0 0 0" quat="0.709913 0.704273 -0.000363156 0.00475427" mass="0.032" diaginertia="4.7981e-06 4.23406e-06 2.86184e-06" />
                          <joint name="pip" pos="0 0 0" axis="0 0 -1" range="-1.047 1.047" actuatorfrcrange="-0.95 0.95" />
                           <geom name="pip_0" pos="0.00964336 0.0003 0.000784034" quat="0.5 -0.5 -0.5 -0.5" type="mesh" contype="0" conaffinity="0" group="1" rgba="0.74902 0.74902 0.74902 1" mesh="pip" friction="0.5 0.05 0.01"/>
                           <geom name="pip_1" pos="0.00964336 0.0003 0.000784034" quat="0.5 -0.5 -0.5 -0.5" type="mesh" rgba="0.2 0.2 0.2 1" mesh="pip" friction="0.5 0.05 0.01"/>
                        
                        <body name="dip" pos="0.015 0.0143 -0.013" quat="0.5 0.5 -0.5 0.5">
                          <inertial pos="0 0 0" quat="-0.252689 0.659216 0.238844 0.666735" mass="0.037" diaginertia="6.68256e-06 6.24841e-06 5.02002e-06" />
                          <joint name="dip" pos="0 0 0" axis="0 0 -1" range="-0.506 1.885" actuatorfrcrange="-0.95 0.95" />
                           <geom name="dip_0" pos="0.0211334 -0.00843212 0.00978509" quat="0 -1 0 0" type="mesh" contype="0" conaffinity="0" group="1" rgba="0.2 0.2 0.2 1" mesh="dip" friction="0.5 0.05 0.01"/>
                           <geom name="dip_1" pos="0.0211334 -0.00843212 0.00978509" quat="0 -1 0 0" type="mesh" rgba="0.2 0.2 0.2 1" mesh="dip" friction="0.5 0.05 0.01"/>

                          <body name="fingertip" pos="-4.08806e-09 -0.0361 0.0002">
                            <inertial pos="0 0 0" quat="0.706755 0.706755 0.0223155 0.0223155" mass="0.016" diaginertia="3.37527e-06 2.863e-06 1.54873e-06" />
                            <joint name="fingertip" pos="0 0 0" axis="0 0 -1" range="-0.366 2.042" actuatorfrcrange="-0.95 0.95" />
                             <geom name="fingertip_0" pos="0.0132864 -0.00611424 0.0145" quat="0 1 0 0" type="mesh" contype="0" conaffinity="0" group="1" rgba="0.2 0.2 0.2 1" mesh="fingertip" friction="0.5 0.05 0.01"/>
                             <geom name="fingertip_1" pos="0.0132864 -0.00611424 0.0145" quat="0 1 0 0" type="mesh" rgba="0.74902 0.74902 0.74902 1" mesh="fingertip" friction="0.5 0.05 0.01"/>
                          </body>
                        </body>
                      </body>
                    </body>
                    <body name="mcp_joint_2" pos="0.0529048 -0.0126079 0.0867226" quat="-0.500002 0.499998 0.499998 0.500002">
                        <inertial pos="0 0 0" quat="0.388585 0.626468 -0.324549 0.592628" mass="0.044" diaginertia="1.47756e-05 1.31982e-05 6.0802e-06" />
                        <joint name="mcp_joint_2" pos="0 0 0" axis="0 0 -1" range="-0.314 2.23" actuatorfrcrange="-0.95 0.95" />
                        <geom name="mcp_joint_2_0" pos="0.0084069 0.00776624 0.0146574" type="mesh" contype="0" conaffinity="0" group="1" rgba="0.2 0.2 0.2 1" mesh="mcp_joint" friction="3.0 0.02 0.001"/>
                        <geom name="mcp_joint_2_1" pos="0.0084069 0.00776624 0.0146574" type="mesh" rgba="0.2 0.2 0.2 1" mesh="mcp_joint" friction="3.0 0.02 0.001"/>
                      
                      <body name="pip_2" pos="-0.0122 0.0381 0.0145" quat="0.5 -0.5 -0.5 0.5">
                          <inertial pos="0 0 0" quat="0.709913 0.704273 -0.000363156 0.00475427" mass="0.032" diaginertia="4.7981e-06 4.23406e-06 2.86184e-06" />
                          <joint name="pip_2" pos="0 0 0" axis="0 0 -1" range="-1.047 1.047" actuatorfrcrange="-0.95 0.95" />
                           <geom name="pip_2_0" pos="0.00964336 0.0003 0.000784034" quat="0.5 -0.5 -0.5 -0.5" type="mesh" contype="0" conaffinity="0" group="1" rgba="0.74902 0.74902 0.74902 1" mesh="pip" friction="0.5 0.05 0.01"/>
                           <geom name="pip_2_1" pos="0.00964336 0.0003 0.000784034" quat="0.5 -0.5 -0.5 -0.5" type="mesh" rgba="0.2 0.2 0.2 1" mesh="pip" friction="0.5 0.05 0.01"/>
                        
                        <body name="dip_2" pos="0.015 0.0143 -0.013" quat="0.5 0.5 -0.5 0.5">
                          <inertial pos="0 0 0" quat="-0.252689 0.659216 0.238844 0.666735" mass="0.037" diaginertia="6.68256e-06 6.24841e-06 5.02002e-06" />
                          <joint name="dip_2" pos="0 0 0" axis="0 0 -1" range="-0.506 1.885" actuatorfrcrange="-0.95 0.95" />
                          <geom name="dip_2_0" pos="0.0211334 -0.00843212 0.00978509" quat="0 -1 0 0" type="mesh" contype="0" conaffinity="0" group="1" rgba="0.2 0.2 0.2 1" mesh="dip" friction="3.0 0.02 0.001"/>
                          <geom name="dip_2_1" pos="0.0211334 -0.00843212 0.00978509" quat="0 -1 0 0" type="mesh" rgba="0.2 0.2 0.2 1" mesh="dip" friction="3.0 0.02 0.001"/>
                          
                          <body name="fingertip_2" pos="0 -0.0361 0.0002">
                            <inertial pos="0 0 0" quat="0.706755 0.706755 0.0223155 0.0223155" mass="0.016" diaginertia="3.37527e-06 2.863e-06 1.54873e-06" />
                            <joint name="fingertip_2" pos="0 0 0" axis="0 0 -1" range="-0.366 2.042" actuatorfrcrange="-0.95 0.95" />
                            <geom name="fingertip_2_0" pos="0.0132864 -0.00611424 0.0145" quat="0 1 0 0" type="mesh" contype="0" conaffinity="0" group="1" rgba="0.2 0.2 0.2 1" mesh="fingertip" friction="3.0 0.02 0.001"/>
                            <geom name="fingertip_2_1" pos="0.0132864 -0.00611424 0.0145" quat="0 1 0 0" type="mesh" rgba="0.74902 0.74902 0.74902 1" mesh="fingertip" friction="3.0 0.02 0.001"/>
                          </body>
                        </body>
                      </body>
                    </body>
                    <body name="mcp_joint_3" pos="0.0529048 0.0328421 0.0867229" quat="-0.500002 0.499998 0.499998 0.500002">
                        <inertial pos="0 0 0" quat="0.388585 0.626468 -0.324549 0.592628" mass="0.044" diaginertia="1.47756e-05 1.31982e-05 6.0802e-06" />
                        <joint name="mcp_joint_3" pos="0 0 0" axis="0 0 -1" range="-0.314 2.23" actuatorfrcrange="-0.95 0.95" />
                        <geom name="mcp_joint_3_0" pos="0.0084069 0.00776624 0.0146574" type="mesh" contype="0" conaffinity="0" group="1" rgba="0.2 0.2 0.2 1" mesh="mcp_joint" friction="3.0 0.02 0.001"/>
                        <geom name="mcp_joint_3_1" pos="0.0084069 0.00776624 0.0146574" type="mesh" rgba="0.2 0.2 0.2 1" mesh="mcp_joint" friction="3.0 0.02 0.001"/>
                      
                      <body name="pip_3" pos="-0.0122 0.0381 0.0145" quat="0.5 -0.5 -0.5 0.5">
                          <inertial pos="0 0 0" quat="0.709913 0.704273 -0.000363156 0.00475427" mass="0.032" diaginertia="4.7981e-06 4.23406e-06 2.86184e-06" />
                          <joint name="pip_3" pos="0 0 0" axis="0 0 -1" range="-1.047 1.047" actuatorfrcrange="-0.95 0.95" />
                          <geom name="pip_3_0" pos="0.00964336 0.0003 0.000784034" quat="0.5 -0.5 -0.5 -0.5" type="mesh" contype="0" conaffinity="0" group="1" rgba="0.74902 0.74902 0.74902 1" mesh="pip" friction="3.0 0.02 0.001"/>
                          <geom name="pip_3_1" pos="0.00964336 0.0003 0.000784034" quat="0.5 -0.5 -0.5 -0.5" type="mesh" rgba="0.2 0.2 0.2 1" mesh="pip" friction="3.0 0.02 0.001"/>
                        
                        <body name="dip_3" pos="0.015 0.0143 -0.013" quat="0.5 0.5 -0.5 0.5">
                          <inertial pos="0 0 0" quat="-0.252689 0.659216 0.238844 0.666735" mass="0.037" diaginertia="6.68256e-06 6.24841e-06 5.02002e-06" />
                          <joint name="dip_3" pos="0 0 0" axis="0 0 -1" range="-0.506 1.885" actuatorfrcrange="-0.95 0.95" />
                          <geom name="dip_3_0" pos="0.0211334 -0.00843212 0.00978509" quat="0 -1 0 0" type="mesh" contype="0" conaffinity="0" group="1" rgba="0.2 0.2 0.2 1" mesh="dip" friction="3.0 0.02 0.001"/>
                          <geom name="dip_3_1" pos="0.0211334 -0.00843212 0.00978509" quat="0 -1 0 0" type="mesh" rgba="0.2 0.2 0.2 1" mesh="dip" friction="3.0 0.02 0.001"/>
                          
                          <body name="fingertip_3" pos="0 -0.0361 0.0002">
                            <inertial pos="0 0 0" quat="0.706755 0.706755 0.0223155 0.0223155" mass="0.016" diaginertia="3.37527e-06 2.863e-06 1.54873e-06" />
                            <joint name="fingertip_3" pos="0 0 0" axis="0 0 -1" range="-0.366 2.042" actuatorfrcrange="-0.95 0.95" />
                            <geom name="fingertip_3_0" pos="0.0132864 -0.00611424 0.0145" quat="0 1 0 0" type="mesh" contype="0" conaffinity="0" group="1" rgba="0.2 0.2 0.2 1" mesh="fingertip" friction="3.0 0.02 0.001"/>
                            <geom name="fingertip_3_1" pos="0.0132864 -0.00611424 0.0145" quat="0 1 0 0" type="mesh" rgba="0.74902 0.74902 0.74902 1" mesh="fingertip" friction="3.0 0.02 0.001"/>
                          </body>
                        </body>
                      </body>
                    </body>
                    <body name="pip_4" pos="-0.00939525 -0.0337579 0.0896224" quat="-2.59735e-06 0.707107 -2.59735e-06 0.707107">
                      <inertial pos="0 0 0" quat="0.709913 0.704273 -0.000363156 0.00475427" mass="0.032" diaginertia="4.7981e-06 4.23406e-06 2.86184e-06" />
                      <joint name="pip_4" pos="0 0 0" axis="0 0 -1" range="-0.349 2.094" actuatorfrcrange="-0.95 0.95" />
                      <geom name="pip_4_0" pos="-0.00535664 0.0003 0.000784034" quat="0.5 -0.5 -0.5 -0.5" type="mesh" contype="0" conaffinity="0" group="1" rgba="0.74902 0.74902 0.74902 1" mesh="pip" friction="3.0 0.02 0.001"/>
                      <geom name="pip_4_1" pos="-0.00535664 0.0003 0.000784034" quat="0.5 -0.5 -0.5 -0.5" type="mesh" rgba="0.2 0.2 0.2 1" mesh="pip" friction="3.0 0.02 0.001"/>
                      
                      <body name="thumb_pip" pos="0 0.0143 -0.013" quat="0.5 0.5 -0.5 0.5">
                        <inertial pos="0 0 0" mass="0.003" diaginertia="5.93e-07 5.49e-07 2.24e-07" />
                        <joint name="thumb_pip" pos="0 0 0" axis="0 0 -1" range="-0.47 2.443" actuatorfrcrange="-0.95 0.95" />
                        <geom name="thumb_pip_0" pos="0.0119619 0 -0.0158526" quat="0.707107 0.707107 0 0" type="mesh" contype="0" conaffinity="0" group="1" rgba="0.2 0.2 0.2 1" mesh="thumb_pip" friction="3.0 0.02 0.001"/>
                        <geom name="thumb_pip_1" pos="0.0119619 0 -0.0158526" quat="0.707107 0.707107 0 0" type="mesh" rgba="0.2 0.2 0.2 1" mesh="thumb_pip" friction="3.0 0.02 0.001"/>
                        
                        <body name="thumb_dip" pos="0 0.0145 -0.017" quat="0.707107 -0.707107 0 0">
                          <inertial pos="0 0 0" quat="0.708624 0.704906 0.00637342 0.0303153" mass="0.038" diaginertia="8.48742e-06 7.67823e-06 3.82835e-06" />
                          <joint name="thumb_dip" pos="0 0 0" axis="0 0 -1" range="-1.2 1.9" actuatorfrcrange="-0.95 0.95" />
                          <geom name="thumb_dip_0" pos="0.0439687 0.057953 -0.00862868" type="mesh" contype="0" conaffinity="0" group="1" rgba="0.2 0.2 0.2 1" mesh="thumb_dip" friction="3.0 0.02 0.001"/>
                          <geom name="thumb_dip_1" pos="0.0439687 0.057953 -0.00862868" type="mesh" rgba="0.2 0.2 0.2 1" mesh="thumb_dip" friction="3.0 0.02 0.001"/>
                          
                          <body name="thumb_fingertip" pos="0 0.0466 0.0002" quat="0 0 0 1">
                            <inertial pos="0 0 0" quat="0.704307 0.709299 0.006848 -0.0282727" mass="0.049" diaginertia="2.03882e-05 1.98443e-05 4.32049e-06" />
                            <joint name="thumb_fingertip" pos="0 0 0" axis="0 0 -1" range="-1.34 1.88" actuatorfrcrange="-0.95 0.95" />
                            <geom name="thumb_fingertip_0" pos="0.0625595 0.0784597 0.0489929" type="mesh" contype="0" conaffinity="0" group="1" rgba="0.74902 0.74902 0.74902 1" mesh="thumb_fingertip" friction="3.0 0.02 0.001"/>
                            <geom name="thumb_fingertip_1" pos="0.0625595 0.0784597 0.0489929" type="mesh" rgba="0.74902 0.74902 0.74902 1" mesh="thumb_fingertip" friction="3.0 0.02 0.001"/>
                          </body>
                        </body>
                      </body>
                    </body>
                  </body>
                </body>
              </body>
            </body>
          </body>
        </body>
      </body>
    </body>
    <body name="object" pos="0.4 1.25 1.2">
        <inertial pos="0.0 0 0" quat="1 0.0 -0.0 -0.0" mass="0.0768" diaginertia="0.00072000 0.00072000 0.00072000" />
        <joint name='object' type='free' damping="0.1" />
        <geom name='object' type="sphere" size="0.12" solimp="0.9 0.95 0.001" solref="0.01 1.5" density="100" friction="3.0 0.02 0.001" rgba="1.0 0.0 0.0 1" group="0" condim="4" />
    </body>

  </worldbody>
  <contact>
    <exclude body1="link7" body2="thumb_pip" />
    <exclude body1="link7" body2="thumb_dip" />
  </contact>  
  <actuator>

    <motor name="joint1" joint="joint1" ctrllimited="true" ctrlrange="-100 100" gear="1" />
    <motor name="joint2" joint="joint2" ctrllimited="true" ctrlrange="-100 100" gear="1" />
    <motor name="joint3" joint="joint3" ctrllimited="true" ctrlrange="-100 100" gear="1" />
    <motor name="joint4" joint="joint4" ctrllimited="true" ctrlrange="-100 100" gear="1" />
    <motor name="joint5" joint="joint5" ctrllimited="true" ctrlrange="-100 100" gear="1" />
    <motor name="joint6" joint="joint6" ctrllimited="true" ctrlrange="-100 100" gear="1" />
    <motor name="joint7" joint="joint7" ctrllimited="true" ctrlrange="-100 100" gear="1" />


    <position name="mcp_joint" joint="mcp_joint" kp="60.0"  dampratio="0.5"/>
    <position name="pip" joint="pip" kp="10"  dampratio="0.5"/>
    <position name="dip" joint="dip" kp="10"  dampratio="0.5"/>
    <position name="fingertip" joint="fingertip" kp="1"  dampratio="0.5"/>

    <position name="mcp_joint_2" joint="mcp_joint_2" kp="60.0"  dampratio="0.5"/>
    <position name="pip_2" joint="pip_2" kp="10"  dampratio="0.5"/>
    <position name="dip_2" joint="dip_2" kp="10"  dampratio="0.5"/>
    <position name="fingertip_2" joint="fingertip_2" kp="1"  dampratio="0.5"/>

    <position name="mcp_joint_3" joint="mcp_joint_3" kp="60.0"  dampratio="0.5"/>
    <position name="pip_3" joint="pip_3" kp="10"  dampratio="0.5"/>
    <position name="dip_3" joint="dip_3" kp="10"  dampratio="0.5"/>
    <position name="fingertip_3" joint="fingertip_3" kp="1"  dampratio="0.5"/>

    <position name="pip_4" joint="pip_4" kp="60.0"  dampratio="0.5"/>
    <position name="thumb_pip" joint="thumb_pip" kp="10"  dampratio="0.5"/>
    <position name="thumb_dip" joint="thumb_dip" kp="20"  dampratio="0.5"/>
    <position name="thumb_fingertip" joint="thumb_fingertip" kp="1"  dampratio="0.5"/>

    <motor name="object_actuator" joint="object" gear="0 0 1 0 0 0" ctrlrange = "-50 50" />
  </actuator>
</mujoco>